<?xml version="1.0"?>
<robot name="legs_URDF">
  <link name="base">
      <visual>
        <origin xyz="0 0 0" rpy="0 0 0" />
        <geometry>
          <mesh filename="meshes/base_link.STL" />
        </geometry>
        <material>
          <color rgba="0.89804314 0.91372941 0.92549412 1.00000000"/>
        </material>
      </visual>
      <collision>
        <origin xyz="0 0 0.07" rpy="0 0 0" />
        <geometry>
          <box size="0.18 0.2 0.15" />
        </geometry>
      </collision>
      <inertial>
        <origin xyz="0 0 0.0074869" rpy="0 0 0" />
        <mass value="0.6188619" />
        <inertia ixx="0.0013749" ixy="0" ixz="0" iyy="0.0014718" iyz="0" izz="0.0025168" />
      </inertial>
    </link>
  <link name="Link_R0">
      <visual>
        <origin xyz="0 0 0" rpy="0 0 0" />
        <geometry>
          <mesh filename="meshes/Link_R0.STL" />
        </geometry>
        <material>
          <color rgba="0.77255294 0.75294510 0.73333725 1.00000000"/>
        </material>
      </visual>
      <inertial>
        <origin xyz="0.0000344 -0.0297324 0.0000527" rpy="0 0 0" />
        <mass value="0.7356663" />
        <inertia ixx="0.0004923" ixy="0.000001" ixz="0" iyy="0.0004979" iyz="-0.000001" izz="0.0005018" />
      </inertial>
    </link>
  <link name="Link_R1">
      <visual>
        <origin xyz="0 0 0" rpy="0 0 0" />
        <geometry>
          <mesh filename="meshes/Link_R1.STL" />
        </geometry>
        <material>
          <color rgba="0.89804314 0.91372941 0.92549412 1.00000000"/>
        </material>
      </visual>
      <collision>
        <origin xyz="0 -0.1 0" rpy="-1.5707963 0 1.5707963" />
        <geometry>
          <cylinder radius="0.04" length="0.08" />
        </geometry>
      </collision>
      <inertial>
        <origin xyz="-0.0013788 -0.0795199 0.0000709" rpy="0 0 0" />
        <mass value="0.5530088" />
        <inertia ixx="0.0002976" ixy="-0.0000239" ixz="0.0000003" iyy="0.0002785" iyz="0" izz="0.0003644" />
      </inertial>
    </link>
  <link name="Link_R2">
      <visual>
        <origin xyz="0 0 0" rpy="0 0 0" />
        <geometry>
          <mesh filename="meshes/Link_R2.STL" />
        </geometry>
        <material>
          <color rgba="0.89804314 0.91372941 0.92549412 1.00000000"/>
        </material>
      </visual>
      <collision>
        <origin xyz="0 0 -0.1" rpy="0 0 0" />
        <geometry>
          <cylinder radius="0.04" length="0.1" />
        </geometry>
      </collision>
      <inertial>
        <origin xyz="0.0045774 0 -0.0743865" rpy="0 0 0" />
        <mass value="0.5459822" />
        <inertia ixx="0.0003158" ixy="0" ixz="-0.0000331" iyy="0.0003989" iyz="0" izz="0.0003074" />
      </inertial>
    </link>
  <link name="Link_R3">
      <visual>
        <origin xyz="0 0 0" rpy="0 0 0" />
        <geometry>
          <mesh filename="meshes/Link_R3.STL" />
        </geometry>
        <material>
          <color rgba="0.89804314 0.91372941 0.92549412 1.00000000"/>
        </material>
      </visual>
      <collision>
        <origin xyz="0 0 -0.1" rpy="-1.5707963 0 0" />
        <geometry>
          <cylinder radius="0.04" length="0.1" />
        </geometry>
      </collision>
      <inertial>
        <origin xyz="0.0000005 0.0001085 -0.0958044" rpy="0 0 0" />
        <mass value="0.5207862" />
        <inertia ixx="0.0004243" ixy="0" ixz="0" iyy="0.0003483" iyz="0.0000153" izz="0.0002701" />
      </inertial>
    </link>
  <link name="Link_R4">
      <visual>
        <origin xyz="0 0 0" rpy="0 0 0" />
        <geometry>
          <mesh filename="meshes/Link_R4.STL" />
        </geometry>
        <material>
          <color rgba="0.89804314 0.91372941 0.92549412 1.00000000"/>
        </material>
      </visual>
      <collision>
        <origin xyz="0 0 -0.14" rpy="0 0 0" />
        <geometry>
          <cylinder radius="0.04" length="0.15" />
        </geometry>
      </collision>
      <inertial>
        <origin xyz="-0.0000005 -0.002464 -0.1405535" rpy="0 0 0" />
        <mass value="0.8551582" />
        <inertia ixx="0.0005475" ixy="0" ixz="0" iyy="0.0004903" iyz="0.0000278" izz="0.000386" />
      </inertial>
    </link>
  <link name="Link_R5">
      <visual>
        <origin xyz="0 0 0" rpy="0 0 0" />
        <geometry>
          <mesh filename="meshes/Link_R5.STL" />
        </geometry>
        <material>
          <color rgba="1.00000000 1.00000000 1.00000000 1.00000000"/>
        </material>
      </visual>
      <inertial>
        <origin xyz="0.0605483 0.0029049 -0.0030212" rpy="0 0 0" />
        <mass value="0.4048744" />
        <inertia ixx="0.0001794" ixy="0.0000034" ixz="-0.0000096" iyy="0.0001738" iyz="-0.000007" izz="0.0001658" />
      </inertial>
    </link>
  <link name="Link_R6">
      <visual>
        <origin xyz="0 0 0" rpy="0 0 0" />
        <geometry>
          <mesh filename="meshes/Link_R6.STL" />
        </geometry>
        <material>
          <color rgba="0.89804314 0.91372941 0.92549412 1.00000000"/>
        </material>
      </visual>
      <collision>
        <origin xyz="0.05 0 -0.0035" rpy="0 0 0" />
        <geometry>
          <box size="0.2 0.08 0.02" />
        </geometry>
      </collision>
      <inertial>
        <origin xyz="0.0523825 0.0000146 -0.0056262" rpy="0 0 0" />
        <mass value="0.3002968" />
        <inertia ixx="0.0001474" ixy="0" ixz="-0.0000001" iyy="0.0007728" iyz="0" izz="0.0009173" />
      </inertial>
    </link>
  <link name="Link_L0">
      <visual>
        <origin xyz="0 0 0" rpy="0 0 0" />
        <geometry>
          <mesh filename="meshes/Link_L0.STL" />
        </geometry>
        <material>
          <color rgba="0.77255294 0.75294510 0.73333725 1.00000000"/>
        </material>
      </visual>
      <inertial>
        <origin xyz="0.0000344 0.0286962 -0.0000527" rpy="0 0 0" />
        <mass value="0.7356663" />
        <inertia ixx="0.0004923" ixy="-0.000001" ixz="0" iyy="0.0004979" iyz="-0.000001" izz="0.0005018" />
      </inertial>
    </link>
  <link name="Link_L1">
      <visual>
        <origin xyz="0 0 0" rpy="0 0 0" />
        <geometry>
          <mesh filename="meshes/Link_L1.STL" />
        </geometry>
        <material>
          <color rgba="0.89804314 0.91372941 0.92549412 1.00000000"/>
        </material>
      </visual>
      <collision>
        <origin xyz="0 0.1 0" rpy="0 1.5707963 0" />
        <geometry>
          <cylinder radius="0.04" length="0.08" />
        </geometry>
      </collision>
      <inertial>
        <origin xyz="-0.0014478 0.0795199 0.0000709" rpy="0 0 0" />
        <mass value="0.5530088" />
        <inertia ixx="0.0002976" ixy="0.0000239" ixz="0.0000003" iyy="0.0002785" iyz="0" izz="0.0003644" />
      </inertial>
    </link>
  <link name="Link_L2">
      <visual>
        <origin xyz="0 0 0" rpy="0 0 0" />
        <geometry>
          <mesh filename="meshes/Link_L2.STL" />
        </geometry>
        <material>
          <color rgba="0.89804314 0.91372941 0.92549412 1.00000000"/>
        </material>
      </visual>
      <collision>
        <origin xyz="0 0 -0.1" rpy="0 0 0" />
        <geometry>
          <cylinder radius="0.04" length="0.1" />
        </geometry>
      </collision>
      <inertial>
        <origin xyz="0.0044774 0 -0.0743865" rpy="0 0 0" />
        <mass value="0.5459822" />
        <inertia ixx="0.0003158" ixy="0" ixz="-0.0000331" iyy="0.0003989" iyz="0" izz="0.0003074" />
      </inertial>
    </link>
  <link name="Link_L3">
      <visual>
        <origin xyz="0 0 0" rpy="0 0 0" />
        <geometry>
          <mesh filename="meshes/Link_L3.STL" />
        </geometry>
        <material>
          <color rgba="0.89804314 0.91372941 0.92549412 1.00000000"/>
        </material>
      </visual>
      <collision>
        <origin xyz="0 0 -0.1" rpy="-1.5707963 0 0" />
        <geometry>
          <cylinder radius="0.04" length="0.1" />
        </geometry>
      </collision>
      <inertial>
        <origin xyz="0 -0.0001081 -0.0958044" rpy="0 0 0" />
        <mass value="0.5207862" />
        <inertia ixx="0.0004243" ixy="0" ixz="0" iyy="0.0003483" iyz="-0.0000153" izz="0.0002701" />
      </inertial>
    </link>
  <link name="Link_L4">
      <visual>
        <origin xyz="0 0 0" rpy="0 0 0" />
        <geometry>
          <mesh filename="meshes/Link_L4.STL" />
        </geometry>
        <material>
          <color rgba="0.89804314 0.91372941 0.92549412 1.00000000"/>
        </material>
      </visual>
      <collision>
        <origin xyz="0 0 -0.14" rpy="0 0 0" />
        <geometry>
          <cylinder radius="0.04" length="0.15" />
        </geometry>
      </collision>
      <inertial>
        <origin xyz="0.0000002 0.0024635 -0.1405535" rpy="0 0 0" />
        <mass value="0.8551582" />
        <inertia ixx="0.0005475" ixy="0" ixz="0" iyy="0.0004903" iyz="-0.0000278" izz="0.000386" />
      </inertial>
    </link>
  <link name="Link_L5">
      <visual>
        <origin xyz="0 0 0" rpy="0 0 0" />
        <geometry>
          <mesh filename="meshes/Link_L5.STL" />
        </geometry>
        <material>
          <color rgba="0.89804314 0.91372941 0.92549412 1.00000000"/>
        </material>
      </visual>
      <inertial>
        <origin xyz="0.0605625 -0.0035236 -0.0030213" rpy="0 0 0" />
        <mass value="0.4048746" />
        <inertia ixx="0.0001794" ixy="-0.0000035" ixz="-0.0000096" iyy="0.0001738" iyz="0.000007" izz="0.0001658" />
      </inertial>
    </link>
  <link name="Link_L6">
      <visual>
        <origin xyz="0 0 0" rpy="0 0 0" />
        <geometry>
          <mesh filename="meshes/Link_L6.STL" />
        </geometry>
        <material>
          <color rgba="0.89804314 0.91372941 0.92549412 1.00000000"/>
        </material>
      </visual>
      <collision>
        <origin xyz="0.05 0 -0.0035" rpy="0 0 0" />
        <geometry>
          <box size="0.2 0.08 0.02" />
        </geometry>
      </collision>
      <inertial>
        <origin xyz="0.0522817 -0.000739 -0.0056262" rpy="0 0 0" />
        <mass value="0.3002968" />
        <inertia ixx="0.0001474" ixy="0" ixz="-0.0000001" iyy="0.0007728" iyz="0" izz="0.0009173" />
      </inertial>
    </link>
  <joint name="joint_R0" type="fixed">
      <parent link="base" />
      <child link="Link_R0" />
      <origin xyz="0 -0.021 0.055" rpy="0 0 0" />
    </joint>
  <joint name="joint_R1" type="revolute">
      <parent link="Link_R0" />
      <child link="Link_R1" />
      <origin xyz="0 -0.06025 0" rpy="0 0 0" />
      <axis xyz="0 1 0" />
      <limit lower="-1.05" upper="1.05" effort="27" velocity="36" />
    </joint>
  <joint name="joint_R2" type="revolute">
      <parent link="Link_R1" />
      <child link="Link_R2" />
      <origin xyz="0 -0.0987 0" rpy="0 0 0" />
      <axis xyz="1 0 0" />
      <limit lower="-1.05" upper="0.26" effort="27" velocity="36" />
    </joint>
  <joint name="joint_R3" type="revolute">
      <parent link="Link_R2" />
      <child link="Link_R3" />
      <origin xyz="0 0 -0.1215" rpy="0 0 0" />
      <axis xyz="0 0 1" />
      <limit lower="-1.00" upper="1.00" effort="27" velocity="36" />
    </joint>
  <joint name="joint_R4" type="revolute">
      <parent link="Link_R3" />
      <child link="Link_R4" />
      <origin xyz="0 0 -0.112" rpy="0 0 0" />
      <axis xyz="0 1 0" />
      <limit lower="0" upper="1.92" effort="27" velocity="36" />
    </joint>
  <joint name="joint_R5" type="revolute">
      <parent link="Link_R4" />
      <child link="Link_R5" />
      <origin xyz="0 0 -0.221" rpy="0 0 0" />
      <axis xyz="0 1 0" />
      <limit lower="-0.52" upper="0.52" effort="7" velocity="120" />
    </joint>
  <joint name="joint_R6" type="revolute">
      <parent link="Link_R5" />
      <child link="Link_R6" />
      <origin xyz="0 0 -0.055093" rpy="0 0 0" />
      <axis xyz="1 0 0" />
      <limit lower="-0.35" upper="0.35" effort="7" velocity="120" />
    </joint>
  <joint name="joint_L0" type="fixed">
      <parent link="base" />
      <child link="Link_L0" />
      <origin xyz="0 0.021 0.055" rpy="0 0 0" />
    </joint>
  <joint name="joint_L1" type="revolute">
      <parent link="Link_L0" />
      <child link="Link_L1" />
      <origin xyz="0 0.06025 0" rpy="0 0 0" />
      <axis xyz="0 1 0" />
      <limit lower="-1.05" upper="1.05" effort="27" velocity="36" />
    </joint>
  <joint name="joint_L2" type="revolute">
      <parent link="Link_L1" />
      <child link="Link_L2" />
      <origin xyz="0 0.0987 0" rpy="0 0 0" />
      <axis xyz="1 0 0" />
      <limit lower="-0.26" upper="1.05" effort="27" velocity="36" />
    </joint>
  <joint name="joint_L3" type="revolute">
      <parent link="Link_L2" />
      <child link="Link_L3" />
      <origin xyz="-0.0001 0 -0.1215" rpy="0 0 0" />
      <axis xyz="0 0 1" />
      <limit lower="-1.00" upper="1.00" effort="27" velocity="36" />
    </joint>
  <joint name="joint_L4" type="revolute">
      <parent link="Link_L3" />
      <child link="Link_L4" />
      <origin xyz="0 0 -0.112" rpy="0 0 0" />
      <axis xyz="0 1 0" />
      <limit lower="0" upper="1.92" effort="27" velocity="36" />
    </joint>
  <joint name="joint_L5" type="revolute">
      <parent link="Link_L4" />
      <child link="Link_L5" />
      <origin xyz="0 0 -0.221" rpy="0 0 0" />
      <axis xyz="0 1 0" />
      <limit lower="-0.52" upper="0.52" effort="7" velocity="120" />
    </joint>
  <joint name="joint_L6" type="revolute">
      <parent link="Link_L5" />
      <child link="Link_L6" />
      <origin xyz="0.0001007 0 -0.055093" rpy="0 0 0" />
      <axis xyz="1 0 0" />
      <limit lower="-0.35" upper="0.35" effort="7" velocity="120" />
    </joint>
</robot>
